Workbook

Sheet Low
A1: Country | B1: Virginia | C1: Oregon | D1: Iowa | E1: Ohio | F1: Texas | G1: Nebraska | H1: Georgia | I1: Oklahoma | J1: Illinois | K1: New Mexico | L1: New York | M1: Alabama | N1: Tennessee | O1: Washington | P1: Utah | Q1: South Carolina | R1: Arizona | S1: North Carolina | T1: Colorado | U1: Nevada | V1: California | W1: Wyoming | X1: Pennsylvania | Y1: Missouri
A3: Year
A5: 2028 | B5: 4.7482374e+10 | C5: 2.2376084e+10 | D5: 1.994314e+10 | E5: 1.5822858e+10 | F5: 1.0185741e+10 | G5: 7.1567814e+09 | H5: 6.9811656e+09 | I5: 6.5203912e+09 | J5: 6.3464985e+09 | K5: 6.2856572e+09 | L5: 5.0424359e+09 | M5: 4.8163957e+09 | N5: 4.7272784e+09 | O5: 4.3476926e+09 | P5: 4.3034582e+09 | Q5: 4.2339074e+09 | R5: 4.0732136e+09 | S5: 2.7072664e+09 | T5: 1.4972783e+09 | U5: 1.3040782e+09 | V5: 1.0041663e+09 | W5: 8.693855e+08 | X5: 5.216313e+08 | Y5: 5.0728122e+08
A6: 2029 | B6: 5.9675573e+10 | C6: 2.8122133e+10 | D6: 2.5064423e+10 | E6: 1.9886076e+10 | F6: 1.2801381e+10 | G6: 8.9946015e+09 | H6: 8.7738885e+09 | I6: 8.19479e+09 | J6: 7.9762426e+09 | K6: 7.8997776e+09 | L6: 6.3373043e+09 | M6: 6.0532182e+09 | N6: 5.9412162e+09 | O6: 5.4641549e+09 | P6: 5.4085614e+09 | Q6: 5.3211503e+09 | R6: 5.1191913e+09 | S6: 3.4024768e+09 | T6: 1.8817707e+09 | U6: 1.638958e+09 | V6: 1.2620304e+09 | W6: 1.0926387e+09 | X6: 6.555832e+08 | Y6: 6.3754811e+08
A7: 2030 | B7: 6.9197026e+10 | C7: 3.2609121e+10 | D7: 2.9063542e+10 | E7: 2.3058971e+10 | F7: 1.4843887e+10 | G7: 1.0429723e+10 | H7: 1.0173794e+10 | I7: 9.5022983e+09 | J7: 9.2488808e+09 | K7: 9.1602155e+09 | L7: 7.348444e+09 | M7: 7.019031e+09 | N7: 6.8891586e+09 | O7: 6.3359805e+09 | P7: 6.2715169e+09 | Q7: 6.170159e+09 | R7: 5.9359768e+09 | S7: 3.9453542e+09 | T7: 2.182014e+09 | U7: 1.9004597e+09 | V7: 1.4633919e+09 | W7: 1.2669731e+09 | X7: 7.6018386e+08 | Y7: 7.392712e+08
A8: 2031 | B8: 7.4354274e+10 | C8: 3.5039475e+10 | D8: 3.1229645e+10 | E8: 2.4777554e+10 | F8: 1.5950201e+10 | G8: 1.1207049e+10 | H8: 1.0932046e+10 | I8: 1.0210504e+10 | J8: 9.9381991e+09 | K8: 9.8429256e+09 | L8: 7.8961229e+09 | M8: 7.5421587e+09 | N8: 7.402607e+09 | O8: 6.8082005e+09 | P8: 6.7389325e+09 | Q8: 6.6300204e+09 | R8: 6.3783846e+09 | S8: 4.2394011e+09 | T8: 2.3446393e+09 | U8: 2.0421007e+09 | V8: 1.5724584e+09 | W8: 1.3614005e+09 | X8: 8.168403e+08 | Y8: 7.9436902e+08
A9: 2032 | B9: 7.4577219e+10 | C9: 3.5144539e+10 | D9: 3.1323285e+10 | E9: 2.4851848e+10 | F9: 1.5998026e+10 | G9: 1.1240652e+10 | H9: 1.0964825e+10 | I9: 1.0241119e+10 | J9: 9.967998e+09 | K9: 9.8724388e+09 | L9: 7.9197988e+09 | M9: 7.5647733e+09 | N9: 7.4248031e+09 | O9: 6.8286144e+09 | P9: 6.7591386e+09 | Q9: 6.6499e+09 | R9: 6.3975097e+09 | S9: 4.2521126e+09 | T9: 2.3516695e+09 | U9: 2.0482238e+09 | V9: 1.5771733e+09 | W9: 1.3654825e+09 | X9: 8.1928953e+08 | Y9: 7.9675087e+08
A10: 2033 | B10: 7.4420939e+10 | C10: 3.5070891e+10 | D10: 3.1257645e+10 | E10: 2.479977e+10 | F10: 1.5964502e+10 | G10: 1.1217097e+10 | H10: 1.0941848e+10 | I10: 1.0219658e+10 | J10: 9.9471096e+09 | K10: 9.8517506e+09 | L10: 7.9032025e+09 | M10: 7.548921e+09 | N10: 7.4092441e+09 | O10: 6.8143047e+09 | P10: 6.7449745e+09 | Q10: 6.6359648e+09 | R10: 6.3841034e+09 | S10: 4.2432021e+09 | T10: 2.3467415e+09 | U10: 2.0439317e+09 | V10: 1.5738683e+09 | W10: 1.3626211e+09 | X10: 8.1757267e+08 | Y10: 7.9508124e+08
A11: 2034 | B11: 7.4360559e+10 | C11: 3.5042437e+10 | D11: 3.1232285e+10 | E11: 2.4779649e+10 | F11: 1.5951549e+10 | G11: 1.1207996e+10 | H11: 1.093297e+10 | I11: 1.0211367e+10 | J11: 9.9390391e+09 | K11: 9.8437575e+09 | L11: 7.8967903e+09 | M11: 7.5427962e+09 | N11: 7.4032327e+09 | O11: 6.808776e+09 | P11: 6.739502e+09 | Q11: 6.6305808e+09 | R11: 6.3789237e+09 | S11: 4.2397595e+09 | T11: 2.3448375e+09 | U11: 2.0422733e+09 | V11: 1.5725913e+09 | W11: 1.3615156e+09 | X11: 8.1690934e+08 | Y11: 7.9443616e+08
A12: 2035 | B12: 7.4350087e+10 | C12: 3.5037502e+10 | D12: 3.1227886e+10 | E12: 2.4776159e+10 | F12: 1.5949303e+10 | G12: 1.1206418e+10 | H12: 1.093143e+10 | I12: 1.0209929e+10 | J12: 9.9376394e+09 | K12: 9.8423713e+09 | L12: 7.8956782e+09 | M12: 7.541734e+09 | N12: 7.4021901e+09 | O12: 6.8078171e+09 | P12: 6.7385529e+09 | Q12: 6.629647e+09 | R12: 6.3780254e+09 | S12: 4.2391624e+09 | T12: 2.3445073e+09 | U12: 2.0419857e+09 | V12: 1.5723699e+09 | W12: 1.3613238e+09 | X12: 8.167943e+08 | Y12: 7.9432429e+08
A14: Solar Capacity (MW) | AA14: Total Solar Capacity (GW)
A16: 2028 | B16: =B5/'Output-Calculation-sheet'!B4*'Output-Calculation-sheet'!B22 -> #DIV/0! | C16: =C5/'Output-Calculation-sheet'!C4*'Output-Calculation-sheet'!C22 -> #DIV/0! | D16: =D5/'Output-Calculation-sheet'!D4*'Output-Calculation-sheet'!D22 -> #DIV/0! | E16: =E5/'Output-Calculation-sheet'!E4*'Output-Calculation-sheet'!E22 -> #DIV/0! | F16: =F5/'Output-Calculation-sheet'!F4*'Output-Calculation-sheet'!F22 -> #DIV/0! | G16: =G5/'Output-Calculation-sheet'!G4*'Output-Calculation-sheet'!G22 -> #DIV/0! | H16: =H5/'Output-Calculation-sheet'!H4*'Output-Calculation-sheet'!H22 -> #DIV/0! | I16: =I5/'Output-Calculation-sheet'!I4*'Output-Calculation-sheet'!I22 -> #DIV/0! | ... Y16: =Y5/'Output-Calculation-sheet'!Y4*'Output-Calculation-sheet'!Y22 -> #DIV/0! | AA16: =SUM(B16:Y16)/1000 -> #DIV/0!
A17: 2029 | B17: =B6/'Output-Calculation-sheet'!B5*'Output-Calculation-sheet'!B23 -> #DIV/0! | C17: =C6/'Output-Calculation-sheet'!C5*'Output-Calculation-sheet'!C23 -> #DIV/0! | D17: =D6/'Output-Calculation-sheet'!D5*'Output-Calculation-sheet'!D23 -> #DIV/0! | E17: =E6/'Output-Calculation-sheet'!E5*'Output-Calculation-sheet'!E23 -> #DIV/0! | F17: =F6/'Output-Calculation-sheet'!F5*'Output-Calculation-sheet'!F23 -> #DIV/0! | G17: =G6/'Output-Calculation-sheet'!G5*'Output-Calculation-sheet'!G23 -> #DIV/0! | H17: =H6/'Output-Calculation-sheet'!H5*'Output-Calculation-sheet'!H23 -> #DIV/0! | I17: =I6/'Output-Calculation-sheet'!I5*'Output-Calculation-sheet'!I23 -> #DIV/0! | ... Y17: =Y6/'Output-Calculation-sheet'!Y5*'Output-Calculation-sheet'!Y23 -> #DIV/0! | AA17: =SUM(B17:Y17)/1000 -> #DIV/0!
A18: 2030 | B18: =B7/'Output-Calculation-sheet'!B6*'Output-Calculation-sheet'!B24 -> #DIV/0! | C18: =C7/'Output-Calculation-sheet'!C6*'Output-Calculation-sheet'!C24 -> #DIV/0! | D18: =D7/'Output-Calculation-sheet'!D6*'Output-Calculation-sheet'!D24 -> #DIV/0! | E18: =E7/'Output-Calculation-sheet'!E6*'Output-Calculation-sheet'!E24 -> #DIV/0! | F18: =F7/'Output-Calculation-sheet'!F6*'Output-Calculation-sheet'!F24 -> #DIV/0! | G18: =G7/'Output-Calculation-sheet'!G6*'Output-Calculation-sheet'!G24 -> #DIV/0! | H18: =H7/'Output-Calculation-sheet'!H6*'Output-Calculation-sheet'!H24 -> #DIV/0! | I18: =I7/'Output-Calculation-sheet'!I6*'Output-Calculation-sheet'!I24 -> #DIV/0! | ... Y18: =Y7/'Output-Calculation-sheet'!Y6*'Output-Calculation-sheet'!Y24 -> #DIV/0! | AA18: =SUM(B18:Y18)/1000 -> #DIV/0!
A19: 2031 | B19: =B8/'Output-Calculation-sheet'!B7*'Output-Calculation-sheet'!B25 -> 826.62553 | C19: =C8/'Output-Calculation-sheet'!C7*'Output-Calculation-sheet'!C25 -> 3889.2454 | D19: =D8/'Output-Calculation-sheet'!D7*'Output-Calculation-sheet'!D25 -> 0 | E19: =E8/'Output-Calculation-sheet'!E7*'Output-Calculation-sheet'!E25 -> 0 | F19: =F8/'Output-Calculation-sheet'!F7*'Output-Calculation-sheet'!F25 -> 0 | G19: =G8/'Output-Calculation-sheet'!G7*'Output-Calculation-sheet'!G25 -> 0 | H19: =H8/'Output-Calculation-sheet'!H7*'Output-Calculation-sheet'!H25 -> 1178.0992 | I19: =I8/'Output-Calculation-sheet'!I7*'Output-Calculation-sheet'!I25 -> 0 | ... Y19: =Y8/'Output-Calculation-sheet'!Y7*'Output-Calculation-sheet'!Y25 -> 0 | AA19: =SUM(B19:Y19)/1000 -> 8.2237654
A20: 2032 | B20: =B9/'Output-Calculation-sheet'!B8*'Output-Calculation-sheet'!B26 -> 3743.0711 | C20: =C9/'Output-Calculation-sheet'!C8*'Output-Calculation-sheet'!C26 -> 2052.6088 | D20: =D9/'Output-Calculation-sheet'!D8*'Output-Calculation-sheet'!D26 -> 0 | E20: =E9/'Output-Calculation-sheet'!E8*'Output-Calculation-sheet'!E26 -> 0 | F20: =F9/'Output-Calculation-sheet'!F8*'Output-Calculation-sheet'!F26 -> 0 | G20: =G9/'Output-Calculation-sheet'!G8*'Output-Calculation-sheet'!G26 -> 0 | H20: =H9/'Output-Calculation-sheet'!H8*'Output-Calculation-sheet'!H26 -> 1232.1912 | I20: =I9/'Output-Calculation-sheet'!I8*'Output-Calculation-sheet'!I26 -> 0 | ... Y20: =Y9/'Output-Calculation-sheet'!Y8*'Output-Calculation-sheet'!Y26 -> 0 | AA20: =SUM(B20:Y20)/1000 -> 9.2634794
A21: 2033 | B21: =B10/'Output-Calculation-sheet'!B9*'Output-Calculation-sheet'!B27 -> 3304.8247 | C21: =C10/'Output-Calculation-sheet'!C9*'Output-Calculation-sheet'!C27 -> 2031.2851 | D21: =D10/'Output-Calculation-sheet'!D9*'Output-Calculation-sheet'!D27 -> 0 | E21: =E10/'Output-Calculation-sheet'!E9*'Output-Calculation-sheet'!E27 -> 0 | F21: =F10/'Output-Calculation-sheet'!F9*'Output-Calculation-sheet'!F27 -> 0 | G21: =G10/'Output-Calculation-sheet'!G9*'Output-Calculation-sheet'!G27 -> 0 | H21: =H10/'Output-Calculation-sheet'!H9*'Output-Calculation-sheet'!H27 -> 666.01124 | I21: =I10/'Output-Calculation-sheet'!I9*'Output-Calculation-sheet'!I27 -> 0 | ... Y21: =Y10/'Output-Calculation-sheet'!Y9*'Output-Calculation-sheet'!Y27 -> 0 | AA21: =SUM(B21:Y21)/1000 -> 7.6284535
A22: 2034 | B22: =B11/'Output-Calculation-sheet'!B10*'Output-Calculation-sheet'!B28 -> 2759.7767 | C22: =C11/'Output-Calculation-sheet'!C10*'Output-Calculation-sheet'!C28 -> 278.02506 | D22: =D11/'Output-Calculation-sheet'!D10*'Output-Calculation-sheet'!D28 -> 0 | E22: =E11/'Output-Calculation-sheet'!E10*'Output-Calculation-sheet'!E28 -> 941.00527 | F22: =F11/'Output-Calculation-sheet'!F10*'Output-Calculation-sheet'!F28 -> 0 | G22: =G11/'Output-Calculation-sheet'!G10*'Output-Calculation-sheet'!G28 -> 0 | H22: =H11/'Output-Calculation-sheet'!H10*'Output-Calculation-sheet'!H28 -> 732.06177 | I22: =I11/'Output-Calculation-sheet'!I10*'Output-Calculation-sheet'!I28 -> 0 | ... Y22: =Y11/'Output-Calculation-sheet'!Y10*'Output-Calculation-sheet'!Y28 -> 20.867478 | AA22: =SUM(B22:Y22)/1000 -> 6.5756342
A23: 2035 | B23: =B12/'Output-Calculation-sheet'!B11*'Output-Calculation-sheet'!B29 -> 609.56127 | C23: =C12/'Output-Calculation-sheet'!C11*'Output-Calculation-sheet'!C29 -> 114.5584 | D23: =D12/'Output-Calculation-sheet'!D11*'Output-Calculation-sheet'!D29 -> 0 | E23: =E12/'Output-Calculation-sheet'!E11*'Output-Calculation-sheet'!E29 -> 1543.4095 | F23: =F12/'Output-Calculation-sheet'!F11*'Output-Calculation-sheet'!F29 -> 0 | G23: =G12/'Output-Calculation-sheet'!G11*'Output-Calculation-sheet'!G29 -> 0 | H23: =H12/'Output-Calculation-sheet'!H11*'Output-Calculation-sheet'!H29 -> 185.82509 | I23: =I12/'Output-Calculation-sheet'!I11*'Output-Calculation-sheet'!I29 -> 0 | ... Y23: =Y12/'Output-Calculation-sheet'!Y11*'Output-Calculation-sheet'!Y29 -> 47.829545 | AA23: =SUM(B23:Y23)/1000 -> 4.0216589
A25: Wind Capacity (MW) | AA25: Total Wind Capacity (GW)
A27: 2028 | B27: =B5/'Output-Calculation-sheet'!B4*'Output-Calculation-sheet'!B13 -> #DIV/0! | C27: =C5/'Output-Calculation-sheet'!C4*'Output-Calculation-sheet'!C13 -> #DIV/0! | D27: =D5/'Output-Calculation-sheet'!D4*'Output-Calculation-sheet'!D13 -> #DIV/0! | E27: =E5/'Output-Calculation-sheet'!E4*'Output-Calculation-sheet'!E13 -> #DIV/0! | F27: =F5/'Output-Calculation-sheet'!F4*'Output-Calculation-sheet'!F13 -> #DIV/0! | G27: =G5/'Output-Calculation-sheet'!G4*'Output-Calculation-sheet'!G13 -> #DIV/0! | H27: =H5/'Output-Calculation-sheet'!H4*'Output-Calculation-sheet'!H13 -> #DIV/0! | I27: =I5/'Output-Calculation-sheet'!I4*'Output-Calculation-sheet'!I13 -> #DIV/0! | ... Y27: =Y5/'Output-Calculation-sheet'!Y4*'Output-Calculation-sheet'!Y13 -> #DIV/0! | AA27: =SUM(B27:Y27)/1000 -> #DIV/0!
A28: 2029 | B28: =B6/'Output-Calculation-sheet'!B5*'Output-Calculation-sheet'!B14 -> #DIV/0! | C28: =C6/'Output-Calculation-sheet'!C5*'Output-Calculation-sheet'!C14 -> #DIV/0! | D28: =D6/'Output-Calculation-sheet'!D5*'Output-Calculation-sheet'!D14 -> #DIV/0! | E28: =E6/'Output-Calculation-sheet'!E5*'Output-Calculation-sheet'!E14 -> #DIV/0! | F28: =F6/'Output-Calculation-sheet'!F5*'Output-Calculation-sheet'!F14 -> #DIV/0! | G28: =G6/'Output-Calculation-sheet'!G5*'Output-Calculation-sheet'!G14 -> #DIV/0! | H28: =H6/'Output-Calculation-sheet'!H5*'Output-Calculation-sheet'!H14 -> #DIV/0! | I28: =I6/'Output-Calculation-sheet'!I5*'Output-Calculation-sheet'!I14 -> #DIV/0! | ... Y28: =Y6/'Output-Calculation-sheet'!Y5*'Output-Calculation-sheet'!Y14 -> #DIV/0! | AA28: =SUM(B28:Y28)/1000 -> #DIV/0!
A29: 2030 | B29: =B7/'Output-Calculation-sheet'!B6*'Output-Calculation-sheet'!B15 -> #DIV/0! | C29: =C7/'Output-Calculation-sheet'!C6*'Output-Calculation-sheet'!C15 -> #DIV/0! | D29: =D7/'Output-Calculation-sheet'!D6*'Output-Calculation-sheet'!D15 -> #DIV/0! | E29: =E7/'Output-Calculation-sheet'!E6*'Output-Calculation-sheet'!E15 -> #DIV/0! | F29: =F7/'Output-Calculation-sheet'!F6*'Output-Calculation-sheet'!F15 -> #DIV/0! | G29: =G7/'Output-Calculation-sheet'!G6*'Output-Calculation-sheet'!G15 -> #DIV/0! | H29: =H7/'Output-Calculation-sheet'!H6*'Output-Calculation-sheet'!H15 -> #DIV/0! | I29: =I7/'Output-Calculation-sheet'!I6*'Output-Calculation-sheet'!I15 -> #DIV/0! | ... Y29: =Y7/'Output-Calculation-sheet'!Y6*'Output-Calculation-sheet'!Y15 -> #DIV/0! | AA29: =SUM(B29:Y29)/1000 -> #DIV/0!
A30: 2031 | B30: =B8/'Output-Calculation-sheet'!B7*'Output-Calculation-sheet'!B16 -> 14408.91 | C30: =C8/'Output-Calculation-sheet'!C7*'Output-Calculation-sheet'!C16 -> 0 | D30: =D8/'Output-Calculation-sheet'!D7*'Output-Calculation-sheet'!D16 -> 2426.2518 | E30: =E8/'Output-Calculation-sheet'!E7*'Output-Calculation-sheet'!E16 -> 2610.5132 | F30: =F8/'Output-Calculation-sheet'!F7*'Output-Calculation-sheet'!F16 -> 1317.0393 | G30: =G8/'Output-Calculation-sheet'!G7*'Output-Calculation-sheet'!G16 -> 862.49286 | H30: =H8/'Output-Calculation-sheet'!H7*'Output-Calculation-sheet'!H16 -> 0 | I30: =I8/'Output-Calculation-sheet'!I7*'Output-Calculation-sheet'!I16 -> 840.81167 | ... Y30: =Y8/'Output-Calculation-sheet'!Y7*'Output-Calculation-sheet'!Y16 -> 90.022979 | AA30: =SUM(B30:Y30)/1000 -> 30.427658
A31: 2032 | B31: =B9/'Output-Calculation-sheet'!B8*'Output-Calculation-sheet'!B17 -> 15737.421 | C31: =C9/'Output-Calculation-sheet'!C8*'Output-Calculation-sheet'!C17 -> 0 | D31: =D9/'Output-Calculation-sheet'!D8*'Output-Calculation-sheet'!D17 -> 3041.9069 | E31: =E9/'Output-Calculation-sheet'!E8*'Output-Calculation-sheet'!E17 -> 3575.3298 | F31: =F9/'Output-Calculation-sheet'!F8*'Output-Calculation-sheet'!F17 -> 1651.2355 | G31: =G9/'Output-Calculation-sheet'!G8*'Output-Calculation-sheet'!G17 -> 1081.349 | H31: =H9/'Output-Calculation-sheet'!H8*'Output-Calculation-sheet'!H17 -> 0 | I31: =I9/'Output-Calculation-sheet'!I8*'Output-Calculation-sheet'!I17 -> 1054.1662 | ... Y31: =Y9/'Output-Calculation-sheet'!Y8*'Output-Calculation-sheet'!Y17 -> 128.84872 | AA31: =SUM(B31:Y31)/1000 -> 36.056297
A32: 2033 | B32: =B10/'Output-Calculation-sheet'!B9*'Output-Calculation-sheet'!B18 -> 11954.425 | C32: =C10/'Output-Calculation-sheet'!C9*'Output-Calculation-sheet'!C18 -> 0 | D32: =D10/'Output-Calculation-sheet'!D9*'Output-Calculation-sheet'!D18 -> 3769.3683 | E32: =E10/'Output-Calculation-sheet'!E9*'Output-Calculation-sheet'!E18 -> 5265.6395 | F32: =F10/'Output-Calculation-sheet'!F9*'Output-Calculation-sheet'!F18 -> 2125.6661 | G32: =G10/'Output-Calculation-sheet'!G9*'Output-Calculation-sheet'!G18 -> 1326.0859 | H32: =H10/'Output-Calculation-sheet'!H9*'Output-Calculation-sheet'!H18 -> 0 | I32: =I10/'Output-Calculation-sheet'!I9*'Output-Calculation-sheet'!I18 -> 1400.0365 | ... Y32: =Y10/'Output-Calculation-sheet'!Y9*'Output-Calculation-sheet'!Y18 -> 190.80458 | AA32: =SUM(B32:Y32)/1000 -> 38.00419
A33: 2034 | B33: =B11/'Output-Calculation-sheet'!B10*'Output-Calculation-sheet'!B19 -> 8329.3857 | C33: =C11/'Output-Calculation-sheet'!C10*'Output-Calculation-sheet'!C19 -> 0 | D33: =D11/'Output-Calculation-sheet'!D10*'Output-Calculation-sheet'!D19 -> 5541.0427 | E33: =E11/'Output-Calculation-sheet'!E10*'Output-Calculation-sheet'!E19 -> 6856.4191 | F33: =F11/'Output-Calculation-sheet'!F10*'Output-Calculation-sheet'!F19 -> 3144.9479 | G33: =G11/'Output-Calculation-sheet'!G10*'Output-Calculation-sheet'!G19 -> 1886.0272 | H33: =H11/'Output-Calculation-sheet'!H10*'Output-Calculation-sheet'!H19 -> 0 | I33: =I11/'Output-Calculation-sheet'!I10*'Output-Calculation-sheet'!I19 -> 2058.1509 | ... Y33: =Y11/'Output-Calculation-sheet'!Y10*'Output-Calculation-sheet'!Y19 -> 204.57293 | AA33: =SUM(B33:Y33)/1000 -> 41.263292
A34: 2035 | B34: =B12/'Output-Calculation-sheet'!B11*'Output-Calculation-sheet'!B20 -> 124.59177 | C34: =C12/'Output-Calculation-sheet'!C11*'Output-Calculation-sheet'!C20 -> 0 | D34: =D12/'Output-Calculation-sheet'!D11*'Output-Calculation-sheet'!D20 -> 5549.273 | E34: =E12/'Output-Calculation-sheet'!E11*'Output-Calculation-sheet'!E20 -> 3275.3641 | F34: =F12/'Output-Calculation-sheet'!F11*'Output-Calculation-sheet'!F20 -> 3790.0878 | G34: =G12/'Output-Calculation-sheet'!G11*'Output-Calculation-sheet'!G20 -> 2043.8982 | H34: =H12/'Output-Calculation-sheet'!H11*'Output-Calculation-sheet'!H20 -> 0 | I34: =I12/'Output-Calculation-sheet'!I11*'Output-Calculation-sheet'!I20 -> 2225.1816 | ... Y34: =Y12/'Output-Calculation-sheet'!Y11*'Output-Calculation-sheet'!Y20 -> 82.896373 | AA34: =SUM(B34:Y34)/1000 -> 29.082303
A36: DAC Capacity (ktCO2/yr) | AA36: Total DAC Capacity (ktCO2/yr)
A38: 2028 | B38: =B5/'Output-Calculation-sheet'!B4*'Output-Calculation-sheet'!B31*0.0114 -> #DIV/0! | C38: =C5/'Output-Calculation-sheet'!C4*'Output-Calculation-sheet'!C31*0.0114 -> #DIV/0! | D38: =D5/'Output-Calculation-sheet'!D4*'Output-Calculation-sheet'!D31*0.0114 -> #DIV/0! | E38: =E5/'Output-Calculation-sheet'!E4*'Output-Calculation-sheet'!E31*0.0114 -> #DIV/0! | F38: =F5/'Output-Calculation-sheet'!F4*'Output-Calculation-sheet'!F31*0.0114 -> #DIV/0! | G38: =G5/'Output-Calculation-sheet'!G4*'Output-Calculation-sheet'!G31*0.0114 -> #DIV/0! | H38: =H5/'Output-Calculation-sheet'!H4*'Output-Calculation-sheet'!H31*0.0114 -> #DIV/0! | I38: =I5/'Output-Calculation-sheet'!I4*'Output-Calculation-sheet'!I31*0.0114 -> #DIV/0! | ... Y38: =Y5/'Output-Calculation-sheet'!Y4*'Output-Calculation-sheet'!Y31*0.0114 -> #DIV/0! | AA38: =SUM(B38:Y38) -> #DIV/0!
A39: 2029 | B39: =B6/'Output-Calculation-sheet'!B5*'Output-Calculation-sheet'!B32*0.0114 -> #DIV/0! | C39: =C6/'Output-Calculation-sheet'!C5*'Output-Calculation-sheet'!C32*0.0114 -> #DIV/0! | D39: =D6/'Output-Calculation-sheet'!D5*'Output-Calculation-sheet'!D32*0.0114 -> #DIV/0! | E39: =E6/'Output-Calculation-sheet'!E5*'Output-Calculation-sheet'!E32*0.0114 -> #DIV/0! | F39: =F6/'Output-Calculation-sheet'!F5*'Output-Calculation-sheet'!F32*0.0114 -> #DIV/0! | G39: =G6/'Output-Calculation-sheet'!G5*'Output-Calculation-sheet'!G32*0.0114 -> #DIV/0! | H39: =H6/'Output-Calculation-sheet'!H5*'Output-Calculation-sheet'!H32*0.0114 -> #DIV/0! | I39: =I6/'Output-Calculation-sheet'!I5*'Output-Calculation-sheet'!I32*0.0114 -> #DIV/0! | ... Y39: =Y6/'Output-Calculation-sheet'!Y5*'Output-Calculation-sheet'!Y32*0.0114 -> #DIV/0! | AA39: =SUM(B39:Y39) -> #DIV/0!
A40: 2030 | B40: =B7/'Output-Calculation-sheet'!B6*'Output-Calculation-sheet'!B33*0.0114 -> #DIV/0! | C40: =C7/'Output-Calculation-sheet'!C6*'Output-Calculation-sheet'!C33*0.0114 -> #DIV/0! | D40: =D7/'Output-Calculation-sheet'!D6*'Output-Calculation-sheet'!D33*0.0114 -> #DIV/0! | E40: =E7/'Output-Calculation-sheet'!E6*'Output-Calculation-sheet'!E33*0.0114 -> #DIV/0! | F40: =F7/'Output-Calculation-sheet'!F6*'Output-Calculation-sheet'!F33*0.0114 -> #DIV/0! | G40: =G7/'Output-Calculation-sheet'!G6*'Output-Calculation-sheet'!G33*0.0114 -> #DIV/0! | H40: =H7/'Output-Calculation-sheet'!H6*'Output-Calculation-sheet'!H33*0.0114 -> #DIV/0! | I40: =I7/'Output-Calculation-sheet'!I6*'Output-Calculation-sheet'!I33*0.0114 -> #DIV/0! | ... Y40: =Y7/'Output-Calculation-sheet'!Y6*'Output-Calculation-sheet'!Y33*0.0114 -> #DIV/0! | AA40: =SUM(B40:Y40) -> #DIV/0!
A41: 2031 | B41: =B8/'Output-Calculation-sheet'!B7*'Output-Calculation-sheet'!B34*0.0114 -> 0 | C41: =C8/'Output-Calculation-sheet'!C7*'Output-Calculation-sheet'!C34*0.0114 -> 0 | D41: =D8/'Output-Calculation-sheet'!D7*'Output-Calculation-sheet'!D34*0.0114 -> 0 | E41: =E8/'Output-Calculation-sheet'!E7*'Output-Calculation-sheet'!E34*0.0114 -> 0 | F41: =F8/'Output-Calculation-sheet'!F7*'Output-Calculation-sheet'!F34*0.0114 -> 0 | G41: =G8/'Output-Calculation-sheet'!G7*'Output-Calculation-sheet'!G34*0.0114 -> 0 | H41: =H8/'Output-Calculation-sheet'!H7*'Output-Calculation-sheet'!H34*0.0114 -> 0 | I41: =I8/'Output-Calculation-sheet'!I7*'Output-Calculation-sheet'!I34*0.0114 -> 0 | ... Y41: =Y8/'Output-Calculation-sheet'!Y7*'Output-Calculation-sheet'!Y34*0.0114 -> 0 | AA41: =SUM(B41:Y41) -> 0
A42: 2032 | B42: =B9/'Output-Calculation-sheet'!B8*'Output-Calculation-sheet'!B35*0.0114 -> 0 | C42: =C9/'Output-Calculation-sheet'!C8*'Output-Calculation-sheet'!C35*0.0114 -> 0 | D42: =D9/'Output-Calculation-sheet'!D8*'Output-Calculation-sheet'!D35*0.0114 -> 0 | E42: =E9/'Output-Calculation-sheet'!E8*'Output-Calculation-sheet'!E35*0.0114 -> 0 | F42: =F9/'Output-Calculation-sheet'!F8*'Output-Calculation-sheet'!F35*0.0114 -> 0 | G42: =G9/'Output-Calculation-sheet'!G8*'Output-Calculation-sheet'!G35*0.0114 -> 0 | H42: =H9/'Output-Calculation-sheet'!H8*'Output-Calculation-sheet'!H35*0.0114 -> 0 | I42: =I9/'Output-Calculation-sheet'!I8*'Output-Calculation-sheet'!I35*0.0114 -> 0 | ... Y42: =Y9/'Output-Calculation-sheet'!Y8*'Output-Calculation-sheet'!Y35*0.0114 -> 0 | AA42: =SUM(B42:Y42) -> 0
A43: 2033 | B43: =B10/'Output-Calculation-sheet'!B9*'Output-Calculation-sheet'!B36*0.0114 -> 0 | C43: =C10/'Output-Calculation-sheet'!C9*'Output-Calculation-sheet'!C36*0.0114 -> 0 | D43: =D10/'Output-Calculation-sheet'!D9*'Output-Calculation-sheet'!D36*0.0114 -> 0 | E43: =E10/'Output-Calculation-sheet'!E9*'Output-Calculation-sheet'!E36*0.0114 -> 0 | F43: =F10/'Output-Calculation-sheet'!F9*'Output-Calculation-sheet'!F36*0.0114 -> 0 | G43: =G10/'Output-Calculation-sheet'!G9*'Output-Calculation-sheet'!G36*0.0114 -> 0 | H43: =H10/'Output-Calculation-sheet'!H9*'Output-Calculation-sheet'!H36*0.0114 -> 0 | I43: =I10/'Output-Calculation-sheet'!I9*'Output-Calculation-sheet'!I36*0.0114 -> 0 | ... Y43: =Y10/'Output-Calculation-sheet'!Y9*'Output-Calculation-sheet'!Y36*0.0114 -> 0 | AA43: =SUM(B43:Y43) -> 0
A44: 2034 | B44: =B11/'Output-Calculation-sheet'!B10*'Output-Calculation-sheet'!B37*0.0114 -> 0 | C44: =C11/'Output-Calculation-sheet'!C10*'Output-Calculation-sheet'!C37*0.0114 -> 0 | D44: =D11/'Output-Calculation-sheet'!D10*'Output-Calculation-sheet'!D37*0.0114 -> 0 | E44: =E11/'Output-Calculation-sheet'!E10*'Output-Calculation-sheet'!E37*0.0114 -> 0 | F44: =F11/'Output-Calculation-sheet'!F10*'Output-Calculation-sheet'!F37*0.0114 -> 0 | G44: =G11/'Output-Calculation-sheet'!G10*'Output-Calculation-sheet'!G37*0.0114 -> 0 | H44: =H11/'Output-Calculation-sheet'!H10*'Output-Calculation-sheet'!H37*0.0114 -> 0 | I44: =I11/'Output-Calculation-sheet'!I10*'Output-Calculation-sheet'!I37*0.0114 -> 0 | ... Y44: =Y11/'Output-Calculation-sheet'!Y10*'Output-Calculation-sheet'!Y37*0.0114 -> 0 | AA44: =SUM(B44:Y44) -> 0
A45: 2035 | B45: =B12/'Output-Calculation-sheet'!B11*'Output-Calculation-sheet'!B38*0.0114 -> 0.082737006 | C45: =C12/'Output-Calculation-sheet'!C11*'Output-Calculation-sheet'!C38*0.0114 -> 0.039268898 | D45: =D12/'Output-Calculation-sheet'!D11*'Output-Calculation-sheet'!D38*0.0114 -> 0.13914185 | E45: =E12/'Output-Calculation-sheet'!E11*'Output-Calculation-sheet'!E38*0.0114 -> 0.082935591 | F45: =F12/'Output-Calculation-sheet'!F11*'Output-Calculation-sheet'!F38*0.0114 -> 0.052160781 | G45: =G12/'Output-Calculation-sheet'!G11*'Output-Calculation-sheet'!G38*0.0114 -> 0.049913328 | H45: =H12/'Output-Calculation-sheet'!H11*'Output-Calculation-sheet'!H38*0.0114 -> 0.012088185 | I45: =I12/'Output-Calculation-sheet'!I11*'Output-Calculation-sheet'!I38*0.0114 -> 0.044893954 | ... Y45: =Y12/'Output-Calculation-sheet'!Y11*'Output-Calculation-sheet'!Y38*0.0114 -> 0.0026416969 | AA45: =SUM(B45:Y45) -> 0.77797999
A47: Battery Storage Capacity (MWh) | AA47: Total Battery Storage Capacity (GWh)
A49: 2028 | B49: =B5/'Output-Calculation-sheet'!B4*'Output-Calculation-sheet'!B40 -> #DIV/0! | C49: =C5/'Output-Calculation-sheet'!C4*'Output-Calculation-sheet'!C40 -> #DIV/0! | D49: =D5/'Output-Calculation-sheet'!D4*'Output-Calculation-sheet'!D40 -> #DIV/0! | E49: =E5/'Output-Calculation-sheet'!E4*'Output-Calculation-sheet'!E40 -> #DIV/0! | F49: =F5/'Output-Calculation-sheet'!F4*'Output-Calculation-sheet'!F40 -> #DIV/0! | G49: =G5/'Output-Calculation-sheet'!G4*'Output-Calculation-sheet'!G40 -> #DIV/0! | H49: =H5/'Output-Calculation-sheet'!H4*'Output-Calculation-sheet'!H40 -> #DIV/0! | I49: =I5/'Output-Calculation-sheet'!I4*'Output-Calculation-sheet'!I40 -> #DIV/0! | ... Y49: =Y5/'Output-Calculation-sheet'!Y4*'Output-Calculation-sheet'!Y40 -> #DIV/0! | AA49: =SUM(B49:Y49)/1000 -> #DIV/0!
A50: 2029 | B50: =B6/'Output-Calculation-sheet'!B5*'Output-Calculation-sheet'!B41 -> #DIV/0! | C50: =C6/'Output-Calculation-sheet'!C5*'Output-Calculation-sheet'!C41 -> #DIV/0! | D50: =D6/'Output-Calculation-sheet'!D5*'Output-Calculation-sheet'!D41 -> #DIV/0! | E50: =E6/'Output-Calculation-sheet'!E5*'Output-Calculation-sheet'!E41 -> #DIV/0! | F50: =F6/'Output-Calculation-sheet'!F5*'Output-Calculation-sheet'!F41 -> #DIV/0! | G50: =G6/'Output-Calculation-sheet'!G5*'Output-Calculation-sheet'!G41 -> #DIV/0! | H50: =H6/'Output-Calculation-sheet'!H5*'Output-Calculation-sheet'!H41 -> #DIV/0! | I50: =I6/'Output-Calculation-sheet'!I5*'Output-Calculation-sheet'!I41 -> #DIV/0! | ... Y50: =Y6/'Output-Calculation-sheet'!Y5*'Output-Calculation-sheet'!Y41 -> #DIV/0! | AA50: =SUM(B50:Y50)/1000 -> #DIV/0!
...

Sheet Peak 2035-Fast-Medium
A1: Country | B1: Virginia | C1: Oregon | D1: Iowa | E1: Ohio | F1: Texas | G1: Nebraska | H1: Georgia | I1: Oklahoma | J1: Illinois | K1: New Mexico | L1: New York | M1: Alabama | N1: Tennessee | O1: Washington | P1: Utah | Q1: South Carolina | R1: Arizona | S1: North Carolina | T1: Colorado | U1: Nevada | V1: California | W1: Wyoming | X1: Pennsylvania | Y1: Missouri
A3: Year
A5: 2028 | B5: 5.115808e+10 | C5: 2.4108262e+10 | D5: 2.1486979e+10 | E5: 1.7047737e+10 | F5: 1.097424e+10 | G5: 7.7108023e+09 | H5: 7.5215916e+09 | I5: 7.0251479e+09 | J5: 6.8377937e+09 | K5: 6.7722425e+09 | L5: 5.432781e+09 | M5: 5.1892426e+09 | N5: 5.0932266e+09 | O5: 4.6842562e+09 | P5: 4.6365976e+09 | Q5: 4.5616627e+09 | R5: 4.3885293e+09 | S5: 2.9168414e+09 | T5: 1.6131856e+09 | U5: 1.4050296e+09 | V5: 1.0819009e+09 | W5: 9.3668638e+08 | X5: 5.6201183e+08 | Y5: 5.4655088e+08
A6: 2029 | B6: 6.8020613e+10 | C6: 3.2054736e+10 | D6: 2.8569435e+10 | E6: 2.2666948e+10 | F6: 1.4591528e+10 | G6: 1.0252408e+10 | H6: 1.000083e+10 | I6: 9.3407506e+09 | J6: 9.0916415e+09 | K6: 9.0044835e+09 | L6: 7.2235138e+09 | M6: 6.8997011e+09 | N6: 6.7720367e+09 | O6: 6.228263e+09 | P6: 6.1648954e+09 | Q6: 6.0652607e+09 | R6: 5.8350598e+09 | S6: 3.8782796e+09 | T6: 2.1449178e+09 | U6: 1.8681501e+09 | V6: 1.4385129e+09 | W6: 1.2454334e+09 | X6: 7.4726004e+08 | Y6: 7.2670292e+08
A7: 2030 | B7: 8.3034356e+10 | C7: 3.9129967e+10 | D7: 3.4875379e+10 | E7: 2.7670074e+10 | F7: 1.781222e+10 | G7: 1.2515354e+10 | H7: 1.2208248e+10 | I7: 1.1402473e+10 | J7: 1.109838e+10 | K7: 1.0991984e+10 | L7: 8.8179125e+09 | M7: 8.4226268e+09 | N7: 8.2667838e+09 | O7: 7.6029866e+09 | P7: 7.5256322e+09 | Q7: 7.4040058e+09 | R7: 7.1229942e+09 | S7: 4.7343068e+09 | T7: 2.6183514e+09 | U7: 2.2804946e+09 | V7: 1.7560265e+09 | W7: 1.5203297e+09 | X7: 9.1219784e+08 | Y7: 8.8710328e+08
A8: 2031 | B8: 9.4207141e+10 | C8: 4.4395145e+10 | D8: 3.9568076e+10 | E8: 3.1393253e+10 | F8: 2.0208964e+10 | G8: 1.4199372e+10 | H8: 1.3850943e+10 | I8: 1.2936746e+10 | J8: 1.2591735e+10 | K8: 1.2471023e+10 | L8: 1.0004417e+10 | M8: 9.5559431e+09 | N8: 9.3791306e+09 | O8: 8.6260153e+09 | P8: 8.5382524e+09 | Q8: 8.4002605e+09 | R8: 8.0814369e+09 | S8: 5.371337e+09 | T8: 2.9706667e+09 | U8: 2.5873492e+09 | V8: 1.9923106e+09 | W8: 1.7248995e+09 | X8: 1.0349397e+09 | Y8: 1.0064685e+09
A9: 2032 | B9: 9.9380644e+10 | C9: 4.6833161e+10 | D9: 4.1741007e+10 | E9: 3.3117253e+10 | F9: 2.1318764e+10 | G9: 1.4979149e+10 | H9: 1.4611585e+10 | I9: 1.3647184e+10 | J9: 1.3283226e+10 | K9: 1.3155885e+10 | L9: 1.0553822e+10 | M9: 1.008072e+10 | N9: 9.8941973e+09 | O9: 9.0997238e+09 | P9: 9.0071413e+09 | Q9: 8.8615713e+09 | R9: 8.5252392e+09 | S9: 5.6663107e+09 | T9: 3.1338046e+09 | U9: 2.7294367e+09 | V9: 2.1017209e+09 | W9: 1.8196245e+09 | X9: 1.0917747e+09 | Y9: 1.06174e+09
A10: 2033 | B10: 1.0005965e+11 | C10: 4.7153144e+10 | D10: 4.2026198e+10 | E10: 3.3343524e+10 | F10: 2.1464423e+10 | G10: 1.5081493e+10 | H10: 1.4711417e+10 | I10: 1.3740427e+10 | J10: 1.3373983e+10 | K10: 1.3245772e+10 | L10: 1.062593e+10 | M10: 1.0149595e+10 | N10: 9.9617985e+09 | O10: 9.1618968e+09 | P10: 9.0686817e+09 | Q10: 8.9221172e+09 | R10: 8.5834871e+09 | S10: 5.7050252e+09 | T10: 3.1552161e+09 | U10: 2.7480854e+09 | V10: 2.1160807e+09 | W10: 1.8320569e+09 | X10: 1.0992341e+09 | Y10: 1.0689942e+09
A11: 2034 | B11: 9.6236314e+10 | C11: 4.5351394e+10 | D11: 4.0420352e+10 | E11: 3.2069448e+10 | F11: 2.0644254e+10 | G11: 1.450522e+10 | H11: 1.4149285e+10 | I11: 1.3215397e+10 | J11: 1.2862955e+10 | K11: 1.2739643e+10 | L11: 1.0219907e+10 | M11: 9.7617732e+09 | N11: 9.5811522e+09 | O11: 8.8118152e+09 | P11: 8.7221619e+09 | Q11: 8.5811977e+09 | R11: 8.2555069e+09 | S11: 5.4870328e+09 | T11: 3.0346533e+09 | U11: 2.6430794e+09 | V11: 2.035224e+09 | W11: 1.7620529e+09 | X11: 1.0572318e+09 | Y11: 1.0281473e+09
A12: 2035 | B12: 8.8070102e+10 | C12: 4.1503064e+10 | D12: 3.699045e+10 | E12: 2.9348168e+10 | F12: 1.8892469e+10 | G12: 1.3274367e+10 | H12: 1.2948636e+10 | I12: 1.2093993e+10 | J12: 1.1771458e+10 | K12: 1.165861e+10 | L12: 9.3526883e+09 | M12: 8.9334298e+09 | N12: 8.7681356e+09 | O12: 8.0640813e+09 | P12: 7.9820357e+09 | Q12: 7.8530331e+09 | R12: 7.554979e+09 | S12: 5.0214261e+09 | T12: 2.7771453e+09 | U12: 2.4187987e+09 | V12: 1.8625234e+09 | W12: 1.6125325e+09 | X12: 9.6751948e+08 | Y12: 9.4090302e+08
A14: Solar Capacity (MW) | AA14: Total Solar Capacity (GW)
A16: 2028 | B16: =B5/'Output-Calculation-sheet'!B4*'Output-Calculation-sheet'!B22 -> #DIV/0! | C16: =C5/'Output-Calculation-sheet'!C4*'Output-Calculation-sheet'!C22 -> #DIV/0! | D16: =D5/'Output-Calculation-sheet'!D4*'Output-Calculation-sheet'!D22 -> #DIV/0! | E16: =E5/'Output-Calculation-sheet'!E4*'Output-Calculation-sheet'!E22 -> #DIV/0! | F16: =F5/'Output-Calculation-sheet'!F4*'Output-Calculation-sheet'!F22 -> #DIV/0! | G16: =G5/'Output-Calculation-sheet'!G4*'Output-Calculation-sheet'!G22 -> #DIV/0! | H16: =H5/'Output-Calculation-sheet'!H4*'Output-Calculation-sheet'!H22 -> #DIV/0! | I16: =I5/'Output-Calculation-sheet'!I4*'Output-Calculation-sheet'!I22 -> #DIV/0! | ... Y16: =Y5/'Output-Calculation-sheet'!Y4*'Output-Calculation-sheet'!Y22 -> #DIV/0! | AA16: =SUM(B16:Y16)/1000 -> #DIV/0!
A17: 2029 | B17: =B6/'Output-Calculation-sheet'!B5*'Output-Calculation-sheet'!B23 -> #DIV/0! | C17: =C6/'Output-Calculation-sheet'!C5*'Output-Calculation-sheet'!C23 -> #DIV/0! | D17: =D6/'Output-Calculation-sheet'!D5*'Output-Calculation-sheet'!D23 -> #DIV/0! | E17: =E6/'Output-Calculation-sheet'!E5*'Output-Calculation-sheet'!E23 -> #DIV/0! | F17: =F6/'Output-Calculation-sheet'!F5*'Output-Calculation-sheet'!F23 -> #DIV/0! | G17: =G6/'Output-Calculation-sheet'!G5*'Output-Calculation-sheet'!G23 -> #DIV/0! | H17: =H6/'Output-Calculation-sheet'!H5*'Output-Calculation-sheet'!H23 -> #DIV/0! | I17: =I6/'Output-Calculation-sheet'!I5*'Output-Calculation-sheet'!I23 -> #DIV/0! | ... Y17: =Y6/'Output-Calculation-sheet'!Y5*'Output-Calculation-sheet'!Y23 -> #DIV/0! | AA17: =SUM(B17:Y17)/1000 -> #DIV/0!
A18: 2030 | B18: =B7/'Output-Calculation-sheet'!B6*'Output-Calculation-sheet'!B24 -> #DIV/0! | C18: =C7/'Output-Calculation-sheet'!C6*'Output-Calculation-sheet'!C24 -> #DIV/0! | D18: =D7/'Output-Calculation-sheet'!D6*'Output-Calculation-sheet'!D24 -> #DIV/0! | E18: =E7/'Output-Calculation-sheet'!E6*'Output-Calculation-sheet'!E24 -> #DIV/0! | F18: =F7/'Output-Calculation-sheet'!F6*'Output-Calculation-sheet'!F24 -> #DIV/0! | G18: =G7/'Output-Calculation-sheet'!G6*'Output-Calculation-sheet'!G24 -> #DIV/0! | H18: =H7/'Output-Calculation-sheet'!H6*'Output-Calculation-sheet'!H24 -> #DIV/0! | I18: =I7/'Output-Calculation-sheet'!I6*'Output-Calculation-sheet'!I24 -> #DIV/0! | ... Y18: =Y7/'Output-Calculation-sheet'!Y6*'Output-Calculation-sheet'!Y24 -> #DIV/0! | AA18: =SUM(B18:Y18)/1000 -> #DIV/0!
A19: 2031 | B19: =B8/'Output-Calculation-sheet'!B7*'Output-Calculation-sheet'!B25 -> 1047.3376 | C19: =C8/'Output-Calculation-sheet'!C7*'Output-Calculation-sheet'!C25 -> 4927.6883 | D19: =D8/'Output-Calculation-sheet'!D7*'Output-Calculation-sheet'!D25 -> 0 | E19: =E8/'Output-Calculation-sheet'!E7*'Output-Calculation-sheet'!E25 -> 0 | F19: =F8/'Output-Calculation-sheet'!F7*'Output-Calculation-sheet'!F25 -> 0 | G19: =G8/'Output-Calculation-sheet'!G7*'Output-Calculation-sheet'!G25 -> 0 | H19: =H8/'Output-Calculation-sheet'!H7*'Output-Calculation-sheet'!H25 -> 1492.656 | I19: =I8/'Output-Calculation-sheet'!I7*'Output-Calculation-sheet'!I25 -> 0 | ... Y19: =Y8/'Output-Calculation-sheet'!Y7*'Output-Calculation-sheet'!Y25 -> 0 | AA19: =SUM(B19:Y19)/1000 -> 10.419541
A20: 2032 | B20: =B9/'Output-Calculation-sheet'!B8*'Output-Calculation-sheet'!B26 -> 4987.9685 | C20: =C9/'Output-Calculation-sheet'!C8*'Output-Calculation-sheet'!C26 -> 2735.2802 | D20: =D9/'Output-Calculation-sheet'!D8*'Output-Calculation-sheet'!D26 -> 0 | E20: =E9/'Output-Calculation-sheet'!E8*'Output-Calculation-sheet'!E26 -> 0 | F20: =F9/'Output-Calculation-sheet'!F8*'Output-Calculation-sheet'!F26 -> 0 | G20: =G9/'Output-Calculation-sheet'!G8*'Output-Calculation-sheet'!G26 -> 0 | H20: =H9/'Output-Calculation-sheet'!H8*'Output-Calculation-sheet'!H26 -> 1642.0022 | I20: =I9/'Output-Calculation-sheet'!I8*'Output-Calculation-sheet'!I26 -> 0 | ... Y20: =Y9/'Output-Calculation-sheet'!Y8*'Output-Calculation-sheet'!Y26 -> 0 | AA20: =SUM(B20:Y20)/1000 -> 12.344394
A21: 2033 | B21: =B10/'Output-Calculation-sheet'!B9*'Output-Calculation-sheet'!B27 -> 4443.3679 | C21: =C10/'Output-Calculation-sheet'!C9*'Output-Calculation-sheet'!C27 -> 2731.0819 | D21: =D10/'Output-Calculation-sheet'!D9*'Output-Calculation-sheet'!D27 -> 0 | E21: =E10/'Output-Calculation-sheet'!E9*'Output-Calculation-sheet'!E27 -> 0 | F21: =F10/'Output-Calculation-sheet'!F9*'Output-Calculation-sheet'!F27 -> 0 | G21: =G10/'Output-Calculation-sheet'!G9*'Output-Calculation-sheet'!G27 -> 0 | H21: =H10/'Output-Calculation-sheet'!H9*'Output-Calculation-sheet'!H27 -> 895.45839 | I21: =I10/'Output-Calculation-sheet'!I9*'Output-Calculation-sheet'!I27 -> 0 | ... Y21: =Y10/'Output-Calculation-sheet'!Y9*'Output-Calculation-sheet'!Y27 -> 0 | AA21: =SUM(B21:Y21)/1000 -> 10.256528
A22: 2034 | B22: =B11/'Output-Calculation-sheet'!B10*'Output-Calculation-sheet'!B28 -> 3571.6614 | C22: =C11/'Output-Calculation-sheet'!C10*'Output-Calculation-sheet'!C28 -> 359.81584 | D22: =D11/'Output-Calculation-sheet'!D10*'Output-Calculation-sheet'!D28 -> 0 | E22: =E11/'Output-Calculation-sheet'!E10*'Output-Calculation-sheet'!E28 -> 1217.8348 | F22: =F11/'Output-Calculation-sheet'!F10*'Output-Calculation-sheet'!F28 -> 0 | G22: =G11/'Output-Calculation-sheet'!G10*'Output-Calculation-sheet'!G28 -> 0 | H22: =H11/'Output-Calculation-sheet'!H10*'Output-Calculation-sheet'!H28 -> 947.4233 | I22: =I11/'Output-Calculation-sheet'!I10*'Output-Calculation-sheet'!I28 -> 0 | ... Y22: =Y11/'Output-Calculation-sheet'!Y10*'Output-Calculation-sheet'!Y28 -> 27.006376 | AA22: =SUM(B22:Y22)/1000 -> 8.5100867
A23: 2035 | B23: =B12/'Output-Calculation-sheet'!B11*'Output-Calculation-sheet'!B29 -> 722.0452 | C23: =C12/'Output-Calculation-sheet'!C11*'Output-Calculation-sheet'!C29 -> 135.69816 | D23: =D12/'Output-Calculation-sheet'!D11*'Output-Calculation-sheet'!D29 -> 0 | E23: =E12/'Output-Calculation-sheet'!E11*'Output-Calculation-sheet'!E29 -> 1828.2189 | F23: =F12/'Output-Calculation-sheet'!F11*'Output-Calculation-sheet'!F29 -> 0 | G23: =G12/'Output-Calculation-sheet'!G11*'Output-Calculation-sheet'!G29 -> 0 | H23: =H12/'Output-Calculation-sheet'!H11*'Output-Calculation-sheet'!H29 -> 220.11588 | I23: =I12/'Output-Calculation-sheet'!I11*'Output-Calculation-sheet'!I29 -> 0 | ... Y23: =Y12/'Output-Calculation-sheet'!Y11*'Output-Calculation-sheet'!Y29 -> 56.655656 | AA23: =SUM(B23:Y23)/1000 -> 4.7637861
A25: Wind Capacity (MW) | AA25: Total Wind Capacity (GW)
A27: 2028 | B27: =B5/'Output-Calculation-sheet'!B4*'Output-Calculation-sheet'!B13 -> #DIV/0! | C27: =C5/'Output-Calculation-sheet'!C4*'Output-Calculation-sheet'!C13 -> #DIV/0! | D27: =D5/'Output-Calculation-sheet'!D4*'Output-Calculation-sheet'!D13 -> #DIV/0! | E27: =E5/'Output-Calculation-sheet'!E4*'Output-Calculation-sheet'!E13 -> #DIV/0! | F27: =F5/'Output-Calculation-sheet'!F4*'Output-Calculation-sheet'!F13 -> #DIV/0! | G27: =G5/'Output-Calculation-sheet'!G4*'Output-Calculation-sheet'!G13 -> #DIV/0! | H27: =H5/'Output-Calculation-sheet'!H4*'Output-Calculation-sheet'!H13 -> #DIV/0! | I27: =I5/'Output-Calculation-sheet'!I4*'Output-Calculation-sheet'!I13 -> #DIV/0! | ... Y27: =Y5/'Output-Calculation-sheet'!Y4*'Output-Calculation-sheet'!Y13 -> #DIV/0! | AA27: =SUM(B27:Y27)/1000 -> #DIV/0!
A28: 2029 | B28: =B6/'Output-Calculation-sheet'!B5*'Output-Calculation-sheet'!B14 -> #DIV/0! | C28: =C6/'Output-Calculation-sheet'!C5*'Output-Calculation-sheet'!C14 -> #DIV/0! | D28: =D6/'Output-Calculation-sheet'!D5*'Output-Calculation-sheet'!D14 -> #DIV/0! | E28: =E6/'Output-Calculation-sheet'!E5*'Output-Calculation-sheet'!E14 -> #DIV/0! | F28: =F6/'Output-Calculation-sheet'!F5*'Output-Calculation-sheet'!F14 -> #DIV/0! | G28: =G6/'Output-Calculation-sheet'!G5*'Output-Calculation-sheet'!G14 -> #DIV/0! | H28: =H6/'Output-Calculation-sheet'!H5*'Output-Calculation-sheet'!H14 -> #DIV/0! | I28: =I6/'Output-Calculation-sheet'!I5*'Output-Calculation-sheet'!I14 -> #DIV/0! | ... Y28: =Y6/'Output-Calculation-sheet'!Y5*'Output-Calculation-sheet'!Y14 -> #DIV/0! | AA28: =SUM(B28:Y28)/1000 -> #DIV/0!
A29: 2030 | B29: =B7/'Output-Calculation-sheet'!B6*'Output-Calculation-sheet'!B15 -> #DIV/0! | C29: =C7/'Output-Calculation-sheet'!C6*'Output-Calculation-sheet'!C15 -> #DIV/0! | D29: =D7/'Output-Calculation-sheet'!D6*'Output-Calculation-sheet'!D15 -> #DIV/0! | E29: =E7/'Output-Calculation-sheet'!E6*'Output-Calculation-sheet'!E15 -> #DIV/0! | F29: =F7/'Output-Calculation-sheet'!F6*'Output-Calculation-sheet'!F15 -> #DIV/0! | G29: =G7/'Output-Calculation-sheet'!G6*'Output-Calculation-sheet'!G15 -> #DIV/0! | H29: =H7/'Output-Calculation-sheet'!H6*'Output-Calculation-sheet'!H15 -> #DIV/0! | I29: =I7/'Output-Calculation-sheet'!I6*'Output-Calculation-sheet'!I15 -> #DIV/0! | ... Y29: =Y7/'Output-Calculation-sheet'!Y6*'Output-Calculation-sheet'!Y15 -> #DIV/0! | AA29: =SUM(B29:Y29)/1000 -> #DIV/0!
A30: 2031 | B30: =B8/'Output-Calculation-sheet'!B7*'Output-Calculation-sheet'!B16 -> 18256.142 | C30: =C8/'Output-Calculation-sheet'!C7*'Output-Calculation-sheet'!C16 -> 0 | D30: =D8/'Output-Calculation-sheet'!D7*'Output-Calculation-sheet'!D16 -> 3074.07 | E30: =E8/'Output-Calculation-sheet'!E7*'Output-Calculation-sheet'!E16 -> 3307.5299 | F30: =F8/'Output-Calculation-sheet'!F7*'Output-Calculation-sheet'!F16 -> 1668.6937 | G30: =G8/'Output-Calculation-sheet'!G7*'Output-Calculation-sheet'!G16 -> 1092.7817 | H30: =H8/'Output-Calculation-sheet'!H7*'Output-Calculation-sheet'!H16 -> 0 | I30: =I8/'Output-Calculation-sheet'!I7*'Output-Calculation-sheet'!I16 -> 1065.3115 | ... Y30: =Y8/'Output-Calculation-sheet'!Y7*'Output-Calculation-sheet'!Y16 -> 114.05945 | AA30: =SUM(B30:Y30)/1000 -> 38.551956
A31: 2032 | B31: =B9/'Output-Calculation-sheet'!B8*'Output-Calculation-sheet'!B17 -> 20971.485 | C31: =C9/'Output-Calculation-sheet'!C8*'Output-Calculation-sheet'!C17 -> 0 | D31: =D9/'Output-Calculation-sheet'!D8*'Output-Calculation-sheet'!D17 -> 4053.606 | E31: =E9/'Output-Calculation-sheet'!E8*'Output-Calculation-sheet'!E17 -> 4764.4385 | F31: =F9/'Output-Calculation-sheet'!F8*'Output-Calculation-sheet'!F17 -> 2200.4152 | G31: =G9/'Output-Calculation-sheet'!G8*'Output-Calculation-sheet'!G17 -> 1440.9918 | H31: =H9/'Output-Calculation-sheet'!H8*'Output-Calculation-sheet'!H17 -> 0 | I31: =I9/'Output-Calculation-sheet'!I8*'Output-Calculation-sheet'!I17 -> 1404.7684 | ... Y31: =Y9/'Output-Calculation-sheet'!Y8*'Output-Calculation-sheet'!Y17 -> 171.70215 | AA31: =SUM(B31:Y31)/1000 -> 48.048159
A32: 2033 | B32: =B10/'Output-Calculation-sheet'!B9*'Output-Calculation-sheet'!B18 -> 16072.836 | C32: =C10/'Output-Calculation-sheet'!C9*'Output-Calculation-sheet'!C18 -> 0 | D32: =D10/'Output-Calculation-sheet'!D9*'Output-Calculation-sheet'!D18 -> 5067.9511 | E32: =E10/'Output-Calculation-sheet'!E9*'Output-Calculation-sheet'!E18 -> 7079.7019 | F32: =F10/'Output-Calculation-sheet'!F9*'Output-Calculation-sheet'!F18 -> 2857.978 | G32: =G10/'Output-Calculation-sheet'!G9*'Output-Calculation-sheet'!G18 -> 1782.935 | H32: =H10/'Output-Calculation-sheet'!H9*'Output-Calculation-sheet'!H18 -> 0 | I32: =I10/'Output-Calculation-sheet'!I9*'Output-Calculation-sheet'!I18 -> 1882.3623 | ... Y32: =Y10/'Output-Calculation-sheet'!Y9*'Output-Calculation-sheet'!Y18 -> 256.53855 | AA32: =SUM(B32:Y32)/1000 -> 51.096992
A33: 2034 | B33: =B11/'Output-Calculation-sheet'!B10*'Output-Calculation-sheet'!B19 -> 10779.765 | C33: =C11/'Output-Calculation-sheet'!C10*'Output-Calculation-sheet'!C19 -> 0 | D33: =D11/'Output-Calculation-sheet'!D10*'Output-Calculation-sheet'!D19 -> 7171.1339 | E33: =E11/'Output-Calculation-sheet'!E10*'Output-Calculation-sheet'!E19 -> 8873.4742 | F33: =F11/'Output-Calculation-sheet'!F10*'Output-Calculation-sheet'!F19 -> 4070.1442 | G33: =G11/'Output-Calculation-sheet'!G10*'Output-Calculation-sheet'!G19 -> 2440.868 | H33: =H11/'Output-Calculation-sheet'!H10*'Output-Calculation-sheet'!H19 -> 0 | I33: =I11/'Output-Calculation-sheet'!I10*'Output-Calculation-sheet'!I19 -> 2663.6279 | ... Y33: =Y11/'Output-Calculation-sheet'!Y10*'Output-Calculation-sheet'!Y19 -> 264.7552 | AA33: =SUM(B33:Y33)/1000 -> 53.40233
A34: 2035 | B34: =B12/'Output-Calculation-sheet'!B11*'Output-Calculation-sheet'!B20 -> 147.58302 | C34: =C12/'Output-Calculation-sheet'!C11*'Output-Calculation-sheet'!C20 -> 0 | D34: =D12/'Output-Calculation-sheet'!D11*'Output-Calculation-sheet'!D20 -> 6573.2948 | E34: =E12/'Output-Calculation-sheet'!E11*'Output-Calculation-sheet'!E20 -> 3879.7756 | F34: =F12/'Output-Calculation-sheet'!F11*'Output-Calculation-sheet'!F20 -> 4489.4825 | G34: =G12/'Output-Calculation-sheet'!G11*'Output-Calculation-sheet'!G20 -> 2421.0641 | H34: =H12/'Output-Calculation-sheet'!H11*'Output-Calculation-sheet'!H20 -> 0 | I34: =I12/'Output-Calculation-sheet'!I11*'Output-Calculation-sheet'!I20 -> 2635.8002 | ... Y34: =Y12/'Output-Calculation-sheet'!Y11*'Output-Calculation-sheet'!Y20 -> 98.193457 | AA34: =SUM(B34:Y34)/1000 -> 34.448936
A36: DAC Capacity (ktCO2/yr) | AA36: Total DAC Capacity (ktCO2/yr)
A38: 2028 | B38: =B5/'Output-Calculation-sheet'!B4*'Output-Calculation-sheet'!B31*0.0114 -> #DIV/0! | C38: =C5/'Output-Calculation-sheet'!C4*'Output-Calculation-sheet'!C31*0.0114 -> #DIV/0! | D38: =D5/'Output-Calculation-sheet'!D4*'Output-Calculation-sheet'!D31*0.0114 -> #DIV/0! | E38: =E5/'Output-Calculation-sheet'!E4*'Output-Calculation-sheet'!E31*0.0114 -> #DIV/0! | F38: =F5/'Output-Calculation-sheet'!F4*'Output-Calculation-sheet'!F31*0.0114 -> #DIV/0! | G38: =G5/'Output-Calculation-sheet'!G4*'Output-Calculation-sheet'!G31*0.0114 -> #DIV/0! | H38: =H5/'Output-Calculation-sheet'!H4*'Output-Calculation-sheet'!H31*0.0114 -> #DIV/0! | I38: =I5/'Output-Calculation-sheet'!I4*'Output-Calculation-sheet'!I31*0.0114 -> #DIV/0! | ... Y38: =Y5/'Output-Calculation-sheet'!Y4*'Output-Calculation-sheet'!Y31*0.0114 -> #DIV/0! | AA38: =SUM(B38:Y38) -> #DIV/0!
A39: 2029 | B39: =B6/'Output-Calculation-sheet'!B5*'Output-Calculation-sheet'!B32*0.0114 -> #DIV/0! | C39: =C6/'Output-Calculation-sheet'!C5*'Output-Calculation-sheet'!C32*0.0114 -> #DIV/0! | D39: =D6/'Output-Calculation-sheet'!D5*'Output-Calculation-sheet'!D32*0.0114 -> #DIV/0! | E39: =E6/'Output-Calculation-sheet'!E5*'Output-Calculation-sheet'!E32*0.0114 -> #DIV/0! | F39: =F6/'Output-Calculation-sheet'!F5*'Output-Calculation-sheet'!F32*0.0114 -> #DIV/0! | G39: =G6/'Output-Calculation-sheet'!G5*'Output-Calculation-sheet'!G32*0.0114 -> #DIV/0! | H39: =H6/'Output-Calculation-sheet'!H5*'Output-Calculation-sheet'!H32*0.0114 -> #DIV/0! | I39: =I6/'Output-Calculation-sheet'!I5*'Output-Calculation-sheet'!I32*0.0114 -> #DIV/0! | ... Y39: =Y6/'Output-Calculation-sheet'!Y5*'Output-Calculation-sheet'!Y32*0.0114 -> #DIV/0! | AA39: =SUM(B39:Y39) -> #DIV/0!
A40: 2030 | B40: =B7/'Output-Calculation-sheet'!B6*'Output-Calculation-sheet'!B33*0.0114 -> #DIV/0! | C40: =C7/'Output-Calculation-sheet'!C6*'Output-Calculation-sheet'!C33*0.0114 -> #DIV/0! | D40: =D7/'Output-Calculation-sheet'!D6*'Output-Calculation-sheet'!D33*0.0114 -> #DIV/0! | E40: =E7/'Output-Calculation-sheet'!E6*'Output-Calculation-sheet'!E33*0.0114 -> #DIV/0! | F40: =F7/'Output-Calculation-sheet'!F6*'Output-Calculation-sheet'!F33*0.0114 -> #DIV/0! | G40: =G7/'Output-Calculation-sheet'!G6*'Output-Calculation-sheet'!G33*0.0114 -> #DIV/0! | H40: =H7/'Output-Calculation-sheet'!H6*'Output-Calculation-sheet'!H33*0.0114 -> #DIV/0! | I40: =I7/'Output-Calculation-sheet'!I6*'Output-Calculation-sheet'!I33*0.0114 -> #DIV/0! | ... Y40: =Y7/'Output-Calculation-sheet'!Y6*'Output-Calculation-sheet'!Y33*0.0114 -> #DIV/0! | AA40: =SUM(B40:Y40) -> #DIV/0!
A41: 2031 | B41: =B8/'Output-Calculation-sheet'!B7*'Output-Calculation-sheet'!B34*0.0114 -> 0 | C41: =C8/'Output-Calculation-sheet'!C7*'Output-Calculation-sheet'!C34*0.0114 -> 0 | D41: =D8/'Output-Calculation-sheet'!D7*'Output-Calculation-sheet'!D34*0.0114 -> 0 | E41: =E8/'Output-Calculation-sheet'!E7*'Output-Calculation-sheet'!E34*0.0114 -> 0 | F41: =F8/'Output-Calculation-sheet'!F7*'Output-Calculation-sheet'!F34*0.0114 -> 0 | G41: =G8/'Output-Calculation-sheet'!G7*'Output-Calculation-sheet'!G34*0.0114 -> 0 | H41: =H8/'Output-Calculation-sheet'!H7*'Output-Calculation-sheet'!H34*0.0114 -> 0 | I41: =I8/'Output-Calculation-sheet'!I7*'Output-Calculation-sheet'!I34*0.0114 -> 0 | ... Y41: =Y8/'Output-Calculation-sheet'!Y7*'Output-Calculation-sheet'!Y34*0.0114 -> 0 | AA41: =SUM(B41:Y41) -> 0
A42: 2032 | B42: =B9/'Output-Calculation-sheet'!B8*'Output-Calculation-sheet'!B35*0.0114 -> 0 | C42: =C9/'Output-Calculation-sheet'!C8*'Output-Calculation-sheet'!C35*0.0114 -> 0 | D42: =D9/'Output-Calculation-sheet'!D8*'Output-Calculation-sheet'!D35*0.0114 -> 0 | E42: =E9/'Output-Calculation-sheet'!E8*'Output-Calculation-sheet'!E35*0.0114 -> 0 | F42: =F9/'Output-Calculation-sheet'!F8*'Output-Calculation-sheet'!F35*0.0114 -> 0 | G42: =G9/'Output-Calculation-sheet'!G8*'Output-Calculation-sheet'!G35*0.0114 -> 0 | H42: =H9/'Output-Calculation-sheet'!H8*'Output-Calculation-sheet'!H35*0.0114 -> 0 | I42: =I9/'Output-Calculation-sheet'!I8*'Output-Calculation-sheet'!I35*0.0114 -> 0 | ... Y42: =Y9/'Output-Calculation-sheet'!Y8*'Output-Calculation-sheet'!Y35*0.0114 -> 0 | AA42: =SUM(B42:Y42) -> 0
A43: 2033 | B43: =B10/'Output-Calculation-sheet'!B9*'Output-Calculation-sheet'!B36*0.0114 -> 0 | C43: =C10/'Output-Calculation-sheet'!C9*'Output-Calculation-sheet'!C36*0.0114 -> 0 | D43: =D10/'Output-Calculation-sheet'!D9*'Output-Calculation-sheet'!D36*0.0114 -> 0 | E43: =E10/'Output-Calculation-sheet'!E9*'Output-Calculation-sheet'!E36*0.0114 -> 0 | F43: =F10/'Output-Calculation-sheet'!F9*'Output-Calculation-sheet'!F36*0.0114 -> 0 | G43: =G10/'Output-Calculation-sheet'!G9*'Output-Calculation-sheet'!G36*0.0114 -> 0 | H43: =H10/'Output-Calculation-sheet'!H9*'Output-Calculation-sheet'!H36*0.0114 -> 0 | I43: =I10/'Output-Calculation-sheet'!I9*'Output-Calculation-sheet'!I36*0.0114 -> 0 | ... Y43: =Y10/'Output-Calculation-sheet'!Y9*'Output-Calculation-sheet'!Y36*0.0114 -> 0 | AA43: =SUM(B43:Y43) -> 0
A44: 2034 | B44: =B11/'Output-Calculation-sheet'!B10*'Output-Calculation-sheet'!B37*0.0114 -> 0 | C44: =C11/'Output-Calculation-sheet'!C10*'Output-Calculation-sheet'!C37*0.0114 -> 0 | D44: =D11/'Output-Calculation-sheet'!D10*'Output-Calculation-sheet'!D37*0.0114 -> 0 | E44: =E11/'Output-Calculation-sheet'!E10*'Output-Calculation-sheet'!E37*0.0114 -> 0 | F44: =F11/'Output-Calculation-sheet'!F10*'Output-Calculation-sheet'!F37*0.0114 -> 0 | G44: =G11/'Output-Calculation-sheet'!G10*'Output-Calculation-sheet'!G37*0.0114 -> 0 | H44: =H11/'Output-Calculation-sheet'!H10*'Output-Calculation-sheet'!H37*0.0114 -> 0 | I44: =I11/'Output-Calculation-sheet'!I10*'Output-Calculation-sheet'!I37*0.0114 -> 0 | ... Y44: =Y11/'Output-Calculation-sheet'!Y10*'Output-Calculation-sheet'!Y37*0.0114 -> 0 | AA44: =SUM(B44:Y44) -> 0
A45: 2035 | B45: =B12/'Output-Calculation-sheet'!B11*'Output-Calculation-sheet'!B38*0.0114 -> 0.098004682 | C45: =C12/'Output-Calculation-sheet'!C11*'Output-Calculation-sheet'!C38*0.0114 -> 0.04651529 | D45: =D12/'Output-Calculation-sheet'!D11*'Output-Calculation-sheet'!D38*0.0114 -> 0.16481806 | E45: =E12/'Output-Calculation-sheet'!E11*'Output-Calculation-sheet'!E38*0.0114 -> 0.098239912 | F45: =F12/'Output-Calculation-sheet'!F11*'Output-Calculation-sheet'!F38*0.0114 -> 0.061786146 | G45: =G12/'Output-Calculation-sheet'!G11*'Output-Calculation-sheet'!G38*0.0114 -> 0.059123964 | H45: =H12/'Output-Calculation-sheet'!H11*'Output-Calculation-sheet'!H38*0.0114 -> 0.014318849 | I45: =I12/'Output-Calculation-sheet'!I11*'Output-Calculation-sheet'!I38*0.0114 -> 0.053178352 | ... Y45: =Y12/'Output-Calculation-sheet'!Y11*'Output-Calculation-sheet'!Y38*0.0114 -> 0.0031291762 | AA45: =SUM(B45:Y45) -> 0.92154267
A47: Battery Storage Capacity (MWh) | AA47: Total Battery Storage Capacity (GWh)
A49: 2028 | B49: =B5/'Output-Calculation-sheet'!B4*'Output-Calculation-sheet'!B40 -> #DIV/0! | C49: =C5/'Output-Calculation-sheet'!C4*'Output-Calculation-sheet'!C40 -> #DIV/0! | D49: =D5/'Output-Calculation-sheet'!D4*'Output-Calculation-sheet'!D40 -> #DIV/0! | E49: =E5/'Output-Calculation-sheet'!E4*'Output-Calculation-sheet'!E40 -> #DIV/0! | F49: =F5/'Output-Calculation-sheet'!F4*'Output-Calculation-sheet'!F40 -> #DIV/0! | G49: =G5/'Output-Calculation-sheet'!G4*'Output-Calculation-sheet'!G40 -> #DIV/0! | H49: =H5/'Output-Calculation-sheet'!H4*'Output-Calculation-sheet'!H40 -> #DIV/0! | I49: =I5/'Output-Calculation-sheet'!I4*'Output-Calculation-sheet'!I40 -> #DIV/0! | ... Y49: =Y5/'Output-Calculation-sheet'!Y4*'Output-Calculation-sheet'!Y40 -> #DIV/0! | AA49: =SUM(B49:Y49)/1000 -> #DIV/0!
A50: 2029 | B50: =B6/'Output-Calculation-sheet'!B5*'Output-Calculation-sheet'!B41 -> #DIV/0! | C50: =C6/'Output-Calculation-sheet'!C5*'Output-Calculation-sheet'!C41 -> #DIV/0! | D50: =D6/'Output-Calculation-sheet'!D5*'Output-Calculation-sheet'!D41 -> #DIV/0! | E50: =E6/'Output-Calculation-sheet'!E5*'Output-Calculation-sheet'!E41 -> #DIV/0! | F50: =F6/'Output-Calculation-sheet'!F5*'Output-Calculation-sheet'!F41 -> #DIV/0! | G50: =G6/'Output-Calculation-sheet'!G5*'Output-Calculation-sheet'!G41 -> #DIV/0! | H50: =H6/'Output-Calculation-sheet'!H5*'Output-Calculation-sheet'!H41 -> #DIV/0! | I50: =I6/'Output-Calculation-sheet'!I5*'Output-Calculation-sheet'!I41 -> #DIV/0! | ... Y50: =Y6/'Output-Calculation-sheet'!Y5*'Output-Calculation-sheet'!Y41 -> #DIV/0! | AA50: =SUM(B50:Y50)/1000 -> #DIV/0!
...

Sheet Peak 2035-Nominal-Medium
A1: Country | B1: Virginia | C1: Oregon | D1: Iowa | E1: Ohio | F1: Texas | G1: Nebraska | H1: Georgia | I1: Oklahoma | J1: Illinois | K1: New Mexico | L1: New York | M1: Alabama | N1: Tennessee | O1: Washington | P1: Utah | Q1: South Carolina | R1: Arizona | S1: North Carolina | T1: Colorado | U1: Nevada | V1: California | W1: Wyoming | X1: Pennsylvania | Y1: Missouri
A3: Year
A5: 2028 | B5: 5.115808e+10 | C5: 2.4108262e+10 | D5: 2.1486979e+10 | E5: 1.7047737e+10 | F5: 1.097424e+10 | G5: 7.7108023e+09 | H5: 7.5215916e+09 | I5: 7.0251479e+09 | J5: 6.8377937e+09 | K5: 6.7722425e+09 | L5: 5.432781e+09 | M5: 5.1892426e+09 | N5: 5.0932266e+09 | O5: 4.6842562e+09 | P5: 4.6365976e+09 | Q5: 4.5616627e+09 | R5: 4.3885293e+09 | S5: 2.9168414e+09 | T5: 1.6131856e+09 | U5: 1.4050296e+09 | V5: 1.0819009e+09 | W5: 9.3668638e+08 | X5: 5.6201183e+08 | Y5: 5.4655088e+08
A6: 2029 | B6: 6.8020613e+10 | C6: 3.2054736e+10 | D6: 2.8569435e+10 | E6: 2.2666948e+10 | F6: 1.4591528e+10 | G6: 1.0252408e+10 | H6: 1.000083e+10 | I6: 9.3407506e+09 | J6: 9.0916415e+09 | K6: 9.0044835e+09 | L6: 7.2235138e+09 | M6: 6.8997011e+09 | N6: 6.7720367e+09 | O6: 6.228263e+09 | P6: 6.1648954e+09 | Q6: 6.0652607e+09 | R6: 5.8350598e+09 | S6: 3.8782796e+09 | T6: 2.1449178e+09 | U6: 1.8681501e+09 | V6: 1.4385129e+09 | W6: 1.2454334e+09 | X6: 7.4726004e+08 | Y6: 7.2670292e+08
A7: 2030 | B7: 8.3034356e+10 | C7: 3.9129967e+10 | D7: 3.4875379e+10 | E7: 2.7670074e+10 | F7: 1.781222e+10 | G7: 1.2515354e+10 | H7: 1.2208248e+10 | I7: 1.1402473e+10 | J7: 1.109838e+10 | K7: 1.0991984e+10 | L7: 8.8179125e+09 | M7: 8.4226268e+09 | N7: 8.2667838e+09 | O7: 7.6029866e+09 | P7: 7.5256322e+09 | Q7: 7.4040058e+09 | R7: 7.1229942e+09 | S7: 4.7343068e+09 | T7: 2.6183514e+09 | U7: 2.2804946e+09 | V7: 1.7560265e+09 | W7: 1.5203297e+09 | X7: 9.1219784e+08 | Y7: 8.8710328e+08
A8: 2031 | B8: 9.5717262e+10 | C8: 4.510679e+10 | D8: 4.0202344e+10 | E8: 3.1896481e+10 | F8: 2.0532909e+10 | G8: 1.4426986e+10 | H8: 1.4072971e+10 | I8: 1.3144119e+10 | J8: 1.2793578e+10 | K8: 1.2670931e+10 | L8: 1.0164786e+10 | M8: 9.7091229e+09 | N8: 9.5294761e+09 | O8: 8.7642885e+09 | P8: 8.6751188e+09 | Q8: 8.5349149e+09 | R8: 8.2109807e+09 | S8: 5.4574384e+09 | T8: 3.0182859e+09 | U8: 2.6288239e+09 | V8: 2.024247e+09 | W8: 1.7525493e+09 | X8: 1.0515296e+09 | Y8: 1.022602e+09
A9: 2032 | B9: 1.0505162e+11 | C9: 4.9505608e+10 | D9: 4.412288e+10 | E9: 3.5007028e+10 | F9: 2.253528e+10 | G9: 1.5833906e+10 | H9: 1.5445368e+10 | I9: 1.4425935e+10 | J9: 1.4041209e+10 | K9: 1.3906601e+10 | L9: 1.1156056e+10 | M9: 1.0655957e+10 | N9: 1.0458791e+10 | O9: 9.6189826e+09 | P9: 9.521117e+09 | Q9: 9.3672404e+09 | R9: 9.0117161e+09 | S9: 5.9896482e+09 | T9: 3.3126294e+09 | U9: 2.885187e+09 | V9: 2.2216517e+09 | W9: 1.923458e+09 | X9: 1.1540748e+09 | Y9: 1.1223262e+09
A10: 2033 | B10: 1.1284456e+11 | C10: 5.3178034e+10 | D10: 4.7396004e+10 | E10: 3.760392e+10 | F10: 2.4206993e+10 | G10: 1.7008497e+10 | H10: 1.6591136e+10 | I10: 1.549608e+10 | J10: 1.5082814e+10 | K10: 1.4938221e+10 | L10: 1.1983635e+10 | M10: 1.1446438e+10 | N10: 1.1234646e+10 | O10: 1.0332538e+10 | P10: 1.0227413e+10 | Q10: 1.0062121e+10 | R10: 9.6802235e+09 | S10: 6.4339724e+09 | T10: 3.5583669e+09 | U10: 3.099216e+09 | V10: 2.3864583e+09 | W10: 2.066144e+09 | X10: 1.2396864e+09 | Y10: 1.2055826e+09
A11: 2034 | B11: 1.1962455e+11 | C11: 5.6373108e+10 | D11: 5.0243679e+10 | E11: 3.9863261e+10 | F11: 2.5661411e+10 | G11: 1.8030412e+10 | H11: 1.7587975e+10 | I11: 1.6427124e+10 | J11: 1.5989028e+10 | K11: 1.5835748e+10 | L11: 1.2703643e+10 | M11: 1.2134169e+10 | N11: 1.1909652e+10 | O11: 1.0953344e+10 | P11: 1.0841902e+10 | Q11: 1.0666679e+10 | R11: 1.0261836e+10 | S11: 6.8205421e+09 | T11: 3.7721628e+09 | U11: 3.2854249e+09 | V11: 2.5298429e+09 | W11: 2.1902833e+09 | X11: 1.31417e+09 | Y11: 1.2780171e+09
A12: 2035 | B12: 1.255454e+11 | C12: 5.9163311e+10 | D12: 5.2730504e+10 | E12: 4.1836304e+10 | F12: 2.693153e+10 | G12: 1.8922832e+10 | H12: 1.8458496e+10 | I12: 1.724019e+10 | J12: 1.678041e+10 | K12: 1.6619543e+10 | L12: 1.3332413e+10 | M12: 1.2734753e+10 | N12: 1.2499124e+10 | O12: 1.1495483e+10 | P12: 1.1378525e+10 | Q12: 1.119463e+10 | R12: 1.0769749e+10 | S12: 7.1581268e+09 | T12: 3.9588671e+09 | U12: 3.4480379e+09 | V12: 2.6550582e+09 | W12: 2.298692e+09 | X12: 1.3792152e+09 | Y12: 1.341273e+09
A14: Solar Capacity (MW) | AA14: Total Solar Capacity (GW)
A16: 2028 | B16: =B5/'Output-Calculation-sheet'!B4*'Output-Calculation-sheet'!B22 -> #DIV/0! | C16: =C5/'Output-Calculation-sheet'!C4*'Output-Calculation-sheet'!C22 -> #DIV/0! | D16: =D5/'Output-Calculation-sheet'!D4*'Output-Calculation-sheet'!D22 -> #DIV/0! | E16: =E5/'Output-Calculation-sheet'!E4*'Output-Calculation-sheet'!E22 -> #DIV/0! | F16: =F5/'Output-Calculation-sheet'!F4*'Output-Calculation-sheet'!F22 -> #DIV/0! | G16: =G5/'Output-Calculation-sheet'!G4*'Output-Calculation-sheet'!G22 -> #DIV/0! | H16: =H5/'Output-Calculation-sheet'!H4*'Output-Calculation-sheet'!H22 -> #DIV/0! | I16: =I5/'Output-Calculation-sheet'!I4*'Output-Calculation-sheet'!I22 -> #DIV/0! | ... Y16: =Y5/'Output-Calculation-sheet'!Y4*'Output-Calculation-sheet'!Y22 -> #DIV/0! | AA16: =SUM(B16:Y16)/1000 -> #DIV/0!
A17: 2029 | B17: =B6/'Output-Calculation-sheet'!B5*'Output-Calculation-sheet'!B23 -> #DIV/0! | C17: =C6/'Output-Calculation-sheet'!C5*'Output-Calculation-sheet'!C23 -> #DIV/0! | D17: =D6/'Output-Calculation-sheet'!D5*'Output-Calculation-sheet'!D23 -> #DIV/0! | E17: =E6/'Output-Calculation-sheet'!E5*'Output-Calculation-sheet'!E23 -> #DIV/0! | F17: =F6/'Output-Calculation-sheet'!F5*'Output-Calculation-sheet'!F23 -> #DIV/0! | G17: =G6/'Output-Calculation-sheet'!G5*'Output-Calculation-sheet'!G23 -> #DIV/0! | H17: =H6/'Output-Calculation-sheet'!H5*'Output-Calculation-sheet'!H23 -> #DIV/0! | I17: =I6/'Output-Calculation-sheet'!I5*'Output-Calculation-sheet'!I23 -> #DIV/0! | ... Y17: =Y6/'Output-Calculation-sheet'!Y5*'Output-Calculation-sheet'!Y23 -> #DIV/0! | AA17: =SUM(B17:Y17)/1000 -> #DIV/0!
A18: 2030 | B18: =B7/'Output-Calculation-sheet'!B6*'Output-Calculation-sheet'!B24 -> #DIV/0! | C18: =C7/'Output-Calculation-sheet'!C6*'Output-Calculation-sheet'!C24 -> #DIV/0! | D18: =D7/'Output-Calculation-sheet'!D6*'Output-Calculation-sheet'!D24 -> #DIV/0! | E18: =E7/'Output-Calculation-sheet'!E6*'Output-Calculation-sheet'!E24 -> #DIV/0! | F18: =F7/'Output-Calculation-sheet'!F6*'Output-Calculation-sheet'!F24 -> #DIV/0! | G18: =G7/'Output-Calculation-sheet'!G6*'Output-Calculation-sheet'!G24 -> #DIV/0! | H18: =H7/'Output-Calculation-sheet'!H6*'Output-Calculation-sheet'!H24 -> #DIV/0! | I18: =I7/'Output-Calculation-sheet'!I6*'Output-Calculation-sheet'!I24 -> #DIV/0! | ... Y18: =Y7/'Output-Calculation-sheet'!Y6*'Output-Calculation-sheet'!Y24 -> #DIV/0! | AA18: =SUM(B18:Y18)/1000 -> #DIV/0!
A19: 2031 | B19: =B8/'Output-Calculation-sheet'!B7*'Output-Calculation-sheet'!B25 -> 1064.1262 | C19: =C8/'Output-Calculation-sheet'!C7*'Output-Calculation-sheet'!C25 -> 5006.6781 | D19: =D8/'Output-Calculation-sheet'!D7*'Output-Calculation-sheet'!D25 -> 0 | E19: =E8/'Output-Calculation-sheet'!E7*'Output-Calculation-sheet'!E25 -> 0 | F19: =F8/'Output-Calculation-sheet'!F7*'Output-Calculation-sheet'!F25 -> 0 | G19: =G8/'Output-Calculation-sheet'!G7*'Output-Calculation-sheet'!G25 -> 0 | H19: =H8/'Output-Calculation-sheet'!H7*'Output-Calculation-sheet'!H25 -> 1516.583 | I19: =I8/'Output-Calculation-sheet'!I7*'Output-Calculation-sheet'!I25 -> 0 | ... Y19: =Y8/'Output-Calculation-sheet'!Y7*'Output-Calculation-sheet'!Y25 -> 0 | AA19: =SUM(B19:Y19)/1000 -> 10.586564
A20: 2032 | B20: =B9/'Output-Calculation-sheet'!B8*'Output-Calculation-sheet'!B26 -> 5272.5977 | C20: =C9/'Output-Calculation-sheet'!C8*'Output-Calculation-sheet'!C26 -> 2891.3638 | D20: =D9/'Output-Calculation-sheet'!D8*'Output-Calculation-sheet'!D26 -> 0 | E20: =E9/'Output-Calculation-sheet'!E8*'Output-Calculation-sheet'!E26 -> 0 | F20: =F9/'Output-Calculation-sheet'!F8*'Output-Calculation-sheet'!F26 -> 0 | G20: =G9/'Output-Calculation-sheet'!G8*'Output-Calculation-sheet'!G26 -> 0 | H20: =H9/'Output-Calculation-sheet'!H8*'Output-Calculation-sheet'!H26 -> 1735.7 | I20: =I9/'Output-Calculation-sheet'!I8*'Output-Calculation-sheet'!I26 -> 0 | ... Y20: =Y9/'Output-Calculation-sheet'!Y8*'Output-Calculation-sheet'!Y26 -> 0 | AA20: =SUM(B20:Y20)/1000 -> 13.048804
